Workbook

Sheet Notes and Guidelines
A1: General guidelines
B2: - Do not assign anyone to a date that they are not available
B3: - Try to evenly distribute standby shifts amongst members.
B4: - Some members with multiple qualifications (i.e CL and Skid Driver, Fireline role and Planning etc may get 1-2 extra shifts to cover those positions)
B5: - Those doing Helitack should do the majority of their standbys as Helitack due to numbers. Helitack members should also get 1-2 extra shifts at their home base
B6: - When using Trainee drivers, a qualified driver needs to be on crew, so for those scenarios use members who are FF and DRV qualified
B7: - A member can only be on standby once per weekend
B8: - Members should not be on standby two weekends in a row where-ever possible.
B9: - Members should not do more than 3 shifts over any rolling 2 month period to prevent burn-out.
A11: Starting point is the AvailabilityFormData which is the data from an online form used by volunteers to submit their availability for the upcoming season.
B12: - Note Column D for those that would like to do more than the average amount of shifts.
B13: - Note Column BD for those that have special conditions that need to be applied
B14: - Note Column BE and BE for those members that would like to do standbys at other bases, typically 1-2 shifts per "Dual Member" where one base might be short.
B15: - Not all members that are qualified and active submit dates so some might need to be assigned dates. This is kept to a minimum to avoid changes and swaps later.
A17: Those dates then map to the standby dates in the VWS Roster tab, using the Quals (Qualifications) tab to define which members can will which positions on those available standbys.
B18: - I've added the Roster Compositions tab to better define what each standby type and per base
B19: - The Role Definitions tab gives an overview of the roles and rules around those roles when allocating.
B20: - Note: Helitack standbys are filled from the Helitack tab instead of from the Quals tab.
A22: Control Roster and Dispatch Roster
B23: - These work with a slightly different shift schedule so this availability is in Control & Dispatch Availability tab
B24: - Control standbys are scheduled on a sperate sheet, compiled on the Control Roster tab
B25: - Dispatch standbys are scheduled on a sperate sheet, compiled on the Dispatch Roster tab
B26: - Note: Members can have standby on the VWS Roster, Control Roster and Dispatch Roster so conflicts must be avoided across these periods
C27: - Control and Dispatch can run simultaneously if requested by the member.
A29: Helpful notes based on how I put this together.
B30: - Start with members with very limited availability on the AvailabilityFormData and schedule them first.
B31: - Next, deal with anyone with conditions and constraints mentioned in AvailabilityFormData Note Column BD
C32: - STB and HDB members that can only do one base
C33: - Partners who preffer to be on standby with their partners.
B34: - Helitack is where I go next based on the limited amount of members on that program.
B35: - Identify dates with the fewest members and fill those first ie over Christmas and New Years, Easter other anomalies where numbers just arent great for that date
C36: - I build this view based on role so I know where the constraints are to prioritise
B37: - Then onto each base individually based on Base Priority and Role Priority
A39: Base Priority
B40: - Helitack
B41: - HDB and STB bases together
B42: - SPS
B43: - NWL, with the view of filling holes in the above rosters with duals
A45: Role Priority when assigning members
B46: - Start with Non-Fireline
...

Sheet Role Definitions
A1: Code | B1: Role | C1: Fireline Role | D1: Standby Roster | E1: Qualification | F1: Rules
A2: CL | B2: Crew Leader | C2: Y | D2: Column E | E2: Column E | F2: Every crew must have a CL, CL spot should take priority over ACL and FF for members with this qualification
A3: ACL | B3: Assistant Crew Leader | C3: Y | D3: Column F | E3: Column F | F3: Every crew except SU must have an ACL, ACL spot should take priority over FF for members with this qualification
A4: ACL (trainee) | B4: Trainee ACL | C4: Y | D4: Column F | E4: Column F | F4: Trainee ACL's should get
A5: FF | B5: Fire Fighter | C5: Y | D5: Column G:J | E5: Column G | F5: Fire fighter role
A6: DRV | B6: Driver | C6: Y | D6: Column M | E6: Column H | F6: Hand crew qualified driver
A7: Drv (trainee) | B7: Driver Trainee | C7: Y | D7: Column M | E7: Column H | F7: Must have a qualified Driver on crew for that standby when using a trainee
A8: Drv (LR only) | B8: Driver | C8: Y | D8: Column M | E8: Column H | F8: Hand crew qualified driver, limited to driving Land Rovers
A9: Drv (LR only trainee) | B9: Driver Trainee | C9: Y | D9: Column M | E9: Column H | F9: Must have a qualified Driver on crew for that standby when using a trainee
A10: SDrv | B10: Skid Unit Driver | C10: Y | D10: Column N | E10: Column I | F10: SU crew types must have a Skid Driver
A11: S Drv (trainee) | B11: Skid Unit Driver Trainee | C11: Y | D11: Column N | E11: Column I | F11: Must have a qualified Skid Driver on crew for that standby when using a trainee
A12: T Drv | B12: Truck Driver | C12: Y | D12: Column M | E12: Column J | F12: Truck driver
... A25: Unfit | B25: Not Fit for Fileline | C25: N/A | D25: Column E | E25: Column O | F25: If flagged as unfit they cannot fill any fire-line roles

Sheet Roster Compositions
A1: VWS Roster Compositions
B2: CL | C2: ACL | D2: FF | E2: FF NR | F2: FF2YR | G2: DRV | H2: SDrv | I2: TDrv | J2: Plan | K2: LS
A3: HDB HC/SU | B3: 1 | C3: 1 | D3: 4 | E3: 2 | G3: 1 | H3: 1 | K3: 1
A4: Helitack STB | B4: 1 | C4: 1 | D4: 3 | F4: 1 | L4: NB: These qualifications are filled from the Helitack Tab
A5: NWL HC1 | B5: 1 | C5: 1 | D5: 4 | E5: 2 | G5: 1 | J5: 46054 | K5: 1
A6: NWL HC2 | B6: 1 | C6: 1 | D6: 4 | E6: 2 | G6: 1
A7: NWL SU | B7: 1 | D7: 1 | E7: 1 | H7: 1
A8: SPS BP | B8: 1 | C8: 2 | D8: 6 | E8: 2 | G8: 1 | I8: 1
A9: SPS HC | B9: 1 | C9: 1 | D9: 4 | E9: 2 | G9: 1
A10: STB HC | B10: 1 | C10: 1 | D10: 4 | E10: 2 | G10: 1
A12: Dispatch Roster Compositions
B13: Disp (mgr) | C13: Disp | D13: Disp (trainee)
A14: Dispatch Manager | B14: 1
A15: Dispatcher | C15: 1
A16: Trainee Dispatcher | D16: 0/1
A18: Control Roster Compositions
B19: Ctrl
A20: Control | B20: 1

Sheet AvailabilityFormData
B1: Timestamp | C1: Which bases would you be willing to do Standbys at? [Primary] | D1: Would you like to do an extra stand by (over and above what will be your normal allocation)? | E1: Which of the following roles do you intend to qualify in? | F1: 45969 | G1: 45970 | H1: 45976 | I1: 45977 | J1: 45983 | K1: 45984 | L1: 45990 | M1: 45991 | N1: 45997 | O1: 45998 | P1: 46004 | Q1: 46005 | R1: 46011 | S1: 46012 | T1: 46018 | U1: 46019 | V1: 46025 | W1: 46026 | X1: 46032 | Y1: 46033 | Z1: 46039 | AA1: 46040 | AB1: 46046 | AC1: 46047 | AD1: 46053 | AE1: 46054 | AF1: 46060 | AG1: 46061 | AH1: 46067 | AI1: 46068 | AJ1: 46074 | AK1: 46075 | AL1: 46081 | AM1: 46082 | AN1: 46088 | AO1: 46089 | AP1: 46095 | AQ1: 46096 | AR1: 46102 | AS1: 46103 | AT1: 46109 | AU1: 46110 | AV1: 46116 | AW1: 46117 | AX1: 46123 | AY1: 46124 | AZ1: 46130 | BA1: 46131 | BB1: 46137 | BC1: 46138 | BD1: Any other notes? | BE1: Which bases would you be willing to do Standbys at? [Secondary] | BF1: Which bases would you be willing to do Standbys at? [Tertiary] | BG1: Do you also intend to qualify in any other roles?
A2: bfbb3d07-9b5c-471c-a36f-b83c04b23fdb | B2: 45935 | C2: South Peninsula | D2: If NWL helitack is run again this year, I would like to opt in | E2: Firefighter, CL, Driver, Planning, Logistical Support, | F2: No | G2: No | H2: No | I2: No | J2: Yes | K2: No | L2: Yes | M2: No | N2: Yes | O2: Yes | P2: No | Q2: No | R2: No | S2: No | T2: No | U2: No | V2: Yes | W2: No | X2: Yes | Y2: No | Z2: Yes | AA2: No | AB2: Yes | AC2: No | AD2: No | AE2: No | AF2: Yes | AG2: No | AH2: No | AI2: No | AJ2: Yes | AK2: No | AL2: Yes | AM2: No | AN2: Yes | AO2: No | AP2: Yes | AQ2: No | AR2: Yes | AS2: No | AT2: No | AU2: No | AV2: No | AW2: No | AX2: Yes | AY2: No | AZ2: Yes | BA2: No | BB2: No | BC2: No | BD2: No Sunday standbys I would like to do the open day standby on 6 December 2025 I would like to do an even split for standbys between SPS and NWL | BE2: Newlands | BF2: Newlands
A3: f2e6f0ab-3fb1-4a94-b8ec-4f9071ea238f | B3: 45950 | C3: Newlands | D3: 1 extra as a firefighter | E3: Firefighter, CL, Driver, Planning, Logistical Support, | F3: Yes | G3: Yes | H3: No | I3: No | J3: No | K3: Yes | L3: No | M3: No | N3: No | O3: No | P3: No | Q3: No | R3: No | S3: No | T3: No | U3: No | V3: No | W3: No | X3: No | Y3: No | Z3: No | AA3: No | AB3: Yes | AC3: Yes | AD3: Yes | AE3: Yes | AF3: Yes | AG3: Yes | AH3: Yes | AI3: Yes | AJ3: Yes | AK3: No | AL3: No | AM3: Yes | AN3: No | AO3: No | AP3: No | AQ3: Yes | AR3: No | AS3: No | AT3: Yes | AU3: No | AV3: No | AW3: No | AX3: Yes | AY3: No | AZ3: No | BA3: Yes | BB3: No | BC3: No | BE3: South Peninsula | BF3: Stellenbosch/Helderberg | BH3: 0
A4: 3ed02464-4cc2-4e1b-af22-0049154b7aea | B4: 45945 | C4: Newlands | D4: 1 extra as a firefighter | E4: Firefighter, CL, Driver, Planning, Logistical Support, | F4: No | G4: No | H4: Yes | I4: Yes | J4: No | K4: No | L4: No | M4: No | N4: Yes | O4: Yes | P4: No | Q4: No | R4: Yes | S4: No | T4: No | U4: No | V4: No | W4: Yes | X4: Yes | Y4: No | Z4: No | AA4: No | AB4: No | AC4: No | AD4: No | AE4: No | AF4: No | AG4: No | AH4: No | AI4: No | AJ4: No | AK4: No | AL4: No | AM4: No | AN4: No | AO4: No | AP4: No | AQ4: No | AR4: No | AS4: No | AT4: No | AU4: No | AV4: No | AW4: No | AX4: No | AY4: No | AZ4: No | BA4: No | BB4: No | BC4: No | BD4: The earlier in season the stanbys are the better. | BE4: Newlands | BF4: Newlands
A5: 95aa57a4-a5ae-4c4d-a413-fbef856e44d8 | B5: 45935 | C5: South Peninsula | D5: I'd rather not, thanks. | E5: Firefighter, CL, Driver, Planning, Logistical Support, | F5: Yes | G5: Yes | H5: No | I5: Yes | J5: No | K5: Yes | L5: No | M5: Yes | N5: Yes | O5: Yes | P5: No | Q5: No | R5: No | S5: No | T5: No | U5: No | V5: No | W5: No | X5: Yes | Y5: Yes | Z5: No | AA5: No | AB5: Yes | AC5: Yes | AD5: Yes | AE5: Yes | AF5: No | AG5: No | AH5: Yes | AI5: Yes | AJ5: Yes | AK5: Yes | AL5: Yes | AM5: Yes | AN5: Yes | AO5: Yes | AP5: Yes | AQ5: Yes | AR5: Yes | AS5: Yes | AT5: No | AU5: No | AV5: No | AW5: No | AX5: No | AY5: No | AZ5: Yes | BA5: Yes | BB5: Yes | BC5: Yes | BD5: Am happy to do 1 of my 4 at NWL, ideally on a Sunday. Please not as an extra. | BE5: Newlands | BF5: N/A
A6: d4472850-8a5d-4c0e-bdaa-4e36076302d0 | B6: 45936 | C6: Newlands | D6: 1 extra as a firefighter | E6: Firefighter, CL, Driver, Planning, Logistical Support, | F6: No | G6: No | H6: Yes | I6: Yes | J6: Yes | K6: Yes | L6: Yes | M6: Yes | N6: Yes | O6: Yes | P6: Yes | Q6: Yes | R6: Yes | S6: No | T6: No | U6: No | V6: Yes | W6: Yes | X6: Yes | Y6: Yes | Z6: Yes | AA6: Yes | AB6: Yes | AC6: Yes | AD6: No | AE6: No | AF6: Yes | AG6: Yes | AH6: Yes | AI6: Yes | AJ6: No | AK6: No | AL6: Yes | AM6: Yes | AN6: No | AO6: No | AP6: Yes | AQ6: Yes | AR6: Yes | AS6: Yes | AT6: Yes | AU6: Yes | AV6: No | AW6: No | AX6: Yes | AY6: Yes | AZ6: Yes | BA6: Yes | BB6: Yes | BC6: Yes | BD6: Must be on with 62ed5d8d-4dbf-464b-b8f3-4b2cd2c973e2 | BE6: South Peninsula | BF6: N/A
A7: 9f7143c0-148c-4a38-a077-99d723fc7d7a | B7: 45937 | C7: Newlands | D7: I'd rather not, thanks. | E7: Firefighter, CL, Driver, Planning, Logistical Support, | F7: No | G7: No | H7: No | I7: No | J7: No | K7: Yes | L7: Yes | M7: Yes | N7: Yes | O7: Yes | P7: Yes | Q7: Yes | R7: No | S7: No | T7: No | U7: No | V7: No | W7: No | X7: No | Y7: No | Z7: No | AA7: Yes | AB7: Yes | AC7: Yes | AD7: Yes | AE7: Yes | AF7: Yes | AG7: Yes | AH7: No | AI7: Yes | AJ7: Yes | AK7: Yes | AL7: Yes | AM7: Yes | AN7: Yes | AO7: Yes | AP7: Yes | AQ7: Yes | AR7: Yes | AS7: Yes | AT7: Yes | AU7: Yes | AV7: Yes | AW7: Yes | AX7: Yes | AY7: Yes | AZ7: Yes | BA7: Yes | BB7: Yes | BC7: Yes | BE7: South Peninsula | BF7: Stellenbosch/Helderberg
A8: 97e21408-df02-4722-8215-91f4962617cc | B8: 45936 | C8: Newlands | D8: I'd rather not, thanks. | E8: Firefighter, CL, Driver, Planning, Logistical Support, | F8: No | G8: No | H8: No | I8: No | J8: Yes | K8: Yes | L8: Yes | M8: Yes | N8: Yes | O8: Yes | P8: Yes | Q8: Yes | R8: No | S8: No | T8: No | U8: No | V8: No | W8: No | X8: No | Y8: Yes | Z8: Yes | AA8: Yes | AB8: Yes | AC8: Yes | AD8: Yes | AE8: Yes | AF8: No | AG8: No | AH8: No | AI8: Yes | AJ8: Yes | AK8: Yes | AL8: Yes | AM8: Yes | AN8: Yes | AO8: Yes | AP8: Yes | AQ8: Yes | AR8: No | AS8: No | AT8: No | AU8: No | AV8: Yes | AW8: Yes | AX8: Yes | AY8: Yes | AZ8: Yes | BA8: Yes | BB8: Yes | BC8: Yes | BE8: South Peninsula | BF8: N/A
A9: 378ce48b-5c37-4a89-b796-316ec088cd7e | B9: 45943 | C9: Stellenbosch/Helderberg | D9: 1 extra as a firefighter | E9: Firefighter, CL, Driver, Planning, Logistical Support, | F9: No | G9: No | H9: No | I9: No | J9: Yes | K9: Yes | L9: Yes | M9: Yes | N9: No | O9: No | P9: Yes | Q9: Yes | R9: Yes | S9: Yes | T9: No | U9: Yes | V9: Yes | W9: Yes | X9: No | Y9: No | Z9: No | AA9: No | AB9: No | AC9: No | AD9: No | AE9: No | AF9: Yes | AG9: Yes | AH9: Yes | AI9: Yes | AJ9: Yes | AK9: Yes | AL9: Yes | AM9: Yes | AN9: Yes | AO9: Yes | AP9: Yes | AQ9: Yes | AR9: Yes | AS9: Yes | AT9: Yes | AU9: Yes | AV9: Yes | AW9: No | AX9: Yes | AY9: Yes | AZ9: Yes | BA9: No | BB9: No | BC9: Yes | BE9: N/A | BF9: N/A
A10: b38b085b-877b-432f-b7bc-959b5fbb2349 | B10: 45944 | C10: South Peninsula, Stellenbosch/Helderberg | D10: 1 extra as a firefighter | E10: Firefighter, CL, Driver, Planning, Logistical Support, | F10: Yes | G10: Yes | H10: Yes | I10: Yes | J10: Yes | K10: Yes | L10: Yes | M10: Yes | N10: Yes | O10: No | P10: Yes | Q10: No | R10: Yes | S10: No | T10: No | U10: No | V10: No | W10: No | X10: Yes | Y10: No | Z10: Yes | AA10: No | AB10: Yes | AC10: No | AD10: Yes | AE10: Yes | AF10: No | AG10: No | AH10: Yes | AI10: Yes | AJ10: Yes | AK10: Yes | AL10: Yes | AM10: No | AN10: Yes | AO10: Yes | AP10: Yes | AQ10: Yes | AR10: No | AS10: No | AT10: Yes | AU10: Yes | AV10: Yes | AW10: Yes | AX10: No | AY10: No | AZ10: Yes | BA10: Yes | BB10: Yes | BC10: Yes | BD10: Dual member with STB/HDB - would prefer those standbys later in the seasin(feb/mar/apr) due to work commitments | BE10: Newlands | BF10: South Peninsula, Stellenbosch/Helderberg
A11: 66f04a65-70c3-4c40-9632-e2adfd956312 | B11: 45936 | C11: Newlands | D11: I'd rather not, thanks. | E11: Firefighter, CL, Driver, Planning, Logistical Support, | F11: Yes | G11: Yes | H11: Yes | I11: Yes | J11: Yes | K11: Yes | L11: Yes | M11: Yes | N11: Yes | O11: Yes | P11: Yes | Q11: Yes | R11: Yes | S11: No | T11: No | U11: No | V11: No | W11: No | X11: Yes | Y11: Yes | Z11: Yes | AA11: Yes | AB11: Yes | AC11: Yes | AD11: Yes | AE11: Yes | AF11: Yes | AG11: Yes | AH11: Yes | AI11: Yes | AJ11: Yes | AK11: Yes | AL11: Yes | AM11: Yes | AN11: Yes | AO11: Yes | AP11: Yes | AQ11: Yes | AR11: Yes | AS11: Yes | AT11: Yes | AU11: Yes | AV11: Yes | AW11: Yes | AX11: Yes | AY11: Yes | AZ11: Yes | BA11: Yes | BB11: Yes | BC11: Yes | BE11: Newlands | BF11: Newlands
A12: 028ef489-2a33-43c6-9d30-c9902ff2f06f | B12: 45933 | C12: Newlands | D12: I'd rather not, thanks. | E12: Firefighter, CL, Driver, Planning, Logistical Support, | F12: No | G12: No | H12: Yes | I12: No | J12: No | K12: No | L12: No | M12: No | N12: Yes | O12: No | P12: No | Q12: No | R12: No | S12: No | T12: No | U12: No | V12: No | W12: No | X12: No | Y12: No | Z12: No | AA12: No | AB12: Yes | AC12: No | AD12: Yes | AE12: No | AF12: Yes | AG12: No | AH12: No | AI12: No | AJ12: No | AK12: No | AL12: No | AM12: No | AN12: No | AO12: No | AP12: No | AQ12: No | AR12: No | AS12: No | AT12: Yes | AU12: No | AV12: No | AW12: No | AX12: No | AY12: No | AZ12: Yes | BA12: No | BB12: Yes | BC12: No | BE12: South Peninsula | BF12: N/A
A13: 896233d3-89f2-4e66-9c1c-fa7e26b26b89 | B13: 45945 | C13: Newlands | D13: 1 extra stand by in a secondary role (eg: as a driver or planning) | E13: Firefighter, CL, Driver, Planning, Logistical Support, | F13: No | G13: No | H13: No | I13: No | J13: No | K13: No | L13: No | M13: No | N13: No | O13: No | P13: No | Q13: No | R13: No | S13: No | T13: No | U13: No | V13: No | W13: No | X13: No | Y13: No | Z13: Yes | AA13: Yes | AB13: Yes | AC13: Yes | AD13: Yes | AE13: Yes | AF13: No | AG13: No | AH13: No | AI13: No | AJ13: Yes | AK13: Yes | AL13: Yes | AM13: Yes | AN13: Yes | AO13: Yes | AP13: Yes | AQ13: Yes | AR13: Yes | AS13: Yes | AT13: Yes | AU13: Yes | AV13: No | AW13: No | AX13: Yes | AY13: Yes | AZ13: No | BA13: No | BB13: Yes | BC13: Yes | BD13: Not available before mid-Jan 2026 | BE13: N/A | BF13: N/A
A14: 9adccede-8dc2-4a5f-b5fd-5edc989b7da6
A15: 7314a85c-bb84-407b-a3d9-dca421f7454f | B15: 45936 | C15: Newlands | D15: If NWL helitack is run again this year, I would like to opt in | E15: Firefighter, CL, Driver, Planning, Logistical Support, | F15: No | G15: No | H15: No | I15: No | J15: No | K15: No | L15: No | M15: No | N15: No | O15: No | P15: No | Q15: No | R15: No | S15: No | T15: No | U15: No | V15: No | W15: No | X15: No | Y15: No | Z15: No | AA15: No | AB15: No | AC15: No | AD15: No | AE15: No | AF15: No | AG15: No | AH15: No | AI15: No | AJ15: No | AK15: No | AL15: No | AM15: No | AN15: No | AO15: No | AP15: No | AQ15: No | AR15: No | AS15: No | AT15: No | AU15: No | AV15: Yes | AW15: No | AX15: No | AY15: No | AZ15: No | BA15: No | BB15: No | BC15: No | BD15: I unfortunately work most weekends and going into summer season the calendar is very upside down. I will definitely have some weekends free but will only be able to confirm much closer to the time. | BE15: N/A | BF15: N/A
A16: 363ca175-a31d-4353-97dc-879dc611455c | B16: 45933 | C16: South Peninsula | D16: 1 extra stand by in a secondary role (eg: as a driver or planning) | E16: Firefighter, CL, Driver, Planning, Logistical Support, | F16: No | G16: No | H16: Yes | I16: No | J16: No | K16: No | L16: No | M16: No | N16: Yes | O16: No | P16: No | Q16: No | R16: Yes | S16: No | T16: No | U16: No | V16: Yes | W16: No | X16: No | Y16: No | Z16: Yes | AA16: No | AB16: No | AC16: No | AD16: Yes | AE16: No | AF16: No | AG16: No | AH16: Yes | AI16: No | AJ16: No | AK16: No | AL16: Yes | AM16: No | AN16: No | AO16: No | AP16: Yes | AQ16: No | AR16: No | AS16: No | AT16: Yes | AU16: No | AV16: No | AW16: No | AX16: Yes | AY16: No | AZ16: No | BA16: No | BB16: Yes | BC16: No | BE16: Newlands | BF16: South Peninsula
A17: 0b396ecd-f02a-41ed-bf0d-ef87ef177e09 | B17: 45933 | C17: South Peninsula | D17: I'd rather not, thanks. | E17: Firefighter, CL, Driver, Planning, Logistical Support, | F17: No | G17: No | H17: Yes | I17: Yes | J17: Yes | K17: Yes | L17: No | M17: No | N17: No | O17: No | P17: Yes | Q17: Yes | R17: No | S17: No | T17: No | U17: No | V17: No | W17: No | X17: Yes | Y17: Yes | Z17: Yes | AA17: Yes | AB17: Yes | AC17: Yes | AD17: Yes | AE17: No | AF17: No | AG17: No | AH17: No | AI17: No | AJ17: No | AK17: No | AL17: No | AM17: No | AN17: No | AO17: No | AP17: No | AQ17: No | AR17: No | AS17: No | AT17: No | AU17: No | AV17: No | AW17: No | AX17: No | AY17: No | AZ17: No | BA17: No | BB17: No | BC17: No | BE17: N/A | BF17: N/A
A18: 02f22d58-165c-40b5-85ec-6db5c37d3a07 | B18: 45950 | C18: Stellenbosch/Helderberg | D18: I'd rather not, thanks. | E18: Firefighter, CL, Driver, Planning, Logistical Support, | F18: No | G18: No | H18: No | I18: Yes | J18: No | K18: No | L18: No | M18: No | N18: No | O18: No | P18: No | Q18: Yes | R18: Yes | S18: No | T18: No | U18: No | V18: No | W18: No | X18: No | Y18: No | Z18: No | AA18: No | AB18: No | AC18: No | AD18: No | AE18: No | AF18: No | AG18: No | AH18: No | AI18: No | AJ18: No | AK18: No | AL18: No | AM18: No | AN18: No | AO18: No | AP18: No | AQ18: No | AR18: No | AS18: No | AT18: No | AU18: No | AV18: No | AW18: No | AX18: No | AY18: No | AZ18: No | BA18: No | BB18: No | BC18: No | BD18: There is a chance that I may need to move to another province at the end of December 2025 subject to where my wife gets allocated for her government medical internship. We expect to be notified before the end of October and I will communicate this with the appropriate person ASAP. | BE18: Newlands | BF18: South Peninsula
A19: d4e5b7b1-714c-47fc-a630-e66c6265e105 | B19: 45935 | C19: Stellenbosch/Helderberg | D19: 1 extra stand by in a secondary role (eg: as a driver or planning) | E19: Firefighter, CL, Driver, Planning, Logistical Support, | F19: No | G19: No | H19: Yes | I19: Yes | J19: No | K19: No | L19: Yes | M19: Yes | N19: Yes | O19: Yes | P19: No | Q19: No | R19: Yes | S19: Yes | T19: No | U19: No | V19: Yes | W19: Yes | X19: Yes | Y19: Yes | Z19: No | AA19: No | AB19: No | AC19: No | AD19: Yes | AE19: Yes | AF19: Yes | AG19: Yes | AH19: No | AI19: No | AJ19: Yes | AK19: Yes | AL19: Yes | AM19: Yes | AN19: No | AO19: No | AP19: No | AQ19: No | AR19: Yes | AS19: Yes | AT19: No | AU19: No | AV19: Yes | AW19: Yes | AX19: No | AY19: No | AZ19: Yes | BA19: Yes | BB19: No | BC19: No | BD19: Can I please be slotted in more for HDB side than STB side | BE19: Newlands | BF19: South Peninsula
A20: 78d662b6-a65d-4b54-b8b9-c79eb0c079f6 | B20: 45945 | C20: Newlands | D20: If NWL helitack is run again this year, I would like to opt in | E20: Firefighter, CL, Driver, Planning, Logistical Support, | F20: No | G20: No | H20: No | I20: Yes | J20: No | K20: No | L20: No | M20: No | N20: No | O20: Yes | P20: No | Q20: No | R20: No | S20: No | T20: No | U20: No | V20: No | W20: No | X20: No | Y20: Yes | Z20: No | AA20: No | AB20: No | AC20: Yes | AD20: No | AE20: No | AF20: No | AG20: Yes | AH20: No | AI20: No | AJ20: No | AK20: Yes | AL20: No | AM20: No | AN20: No | AO20: Yes | AP20: No | AQ20: No | AR20: No | AS20: Yes | AT20: No | AU20: No | AV20: No | AW20: Yes | AX20: No | AY20: No | AZ20: No | BA20: No | BB20: No | BC20: No | BE20: Newlands | BF20: Newlands
A21: 1a2d9bdc-7c4f-404d-9df3-d79d7d25ab99 | B21: 45945 | C21: Newlands | D21: I'd rather not, thanks. | E21: Firefighter, CL, Driver, Planning, Logistical Support, | F21: Yes | G21: Yes | H21: Yes | I21: Yes | J21: Yes | K21: Yes | L21: Yes | M21: Yes | N21: No | O21: No | P21: No | Q21: No | R21: Yes | S21: No | T21: Yes | U21: Yes | V21: Yes | W21: Yes | X21: No | Y21: Yes | Z21: No | AA21: No | AB21: No | AC21: No | AD21: No | AE21: No | AF21: No | AG21: No | AH21: Yes | AI21: No | AJ21: Yes | AK21: Yes | AL21: Yes | AM21: Yes | AN21: No | AO21: Yes | AP21: No | AQ21: No | AR21: No | AS21: No | AT21: No | AU21: No | AV21: No | AW21: No | AX21: Yes | AY21: No | AZ21: Yes | BA21: Yes | BB21: Yes | BC21: Yes | BE21: N/A | BF21: N/A
A22: 10804e44-fc06-4d65-8115-05da4966a5b4 | B22: 45938 | C22: South Peninsula | D22: If NWL helitack is run again this year, I would like to opt in | E22: Firefighter, CL, Driver, Planning, Logistical Support, | F22: No | G22: No | H22: Yes | I22: Yes | J22: Yes | K22: Yes | L22: No | M22: No | N22: No | O22: No | P22: Yes | Q22: Yes | R22: No | S22: No | T22: No | U22: No | V22: Yes | W22: No | X22: Yes | Y22: Yes | Z22: Yes | AA22: Yes | AB22: Yes | AC22: No | AD22: No | AE22: No | AF22: No | AG22: Yes | AH22: Yes | AI22: Yes | AJ22: Yes | AK22: No | AL22: No | AM22: No | AN22: No | AO22: No | AP22: Yes | AQ22: Yes | AR22: Yes | AS22: Yes | AT22: No | AU22: No | AV22: No | AW22: No | AX22: Yes | AY22: Yes | AZ22: Yes | BA22: Yes | BB22: No | BC22: No | BE22: South Peninsula | BF22: South Peninsula
A23: 3e65b11b-e7bb-4f38-bde3-eec32997e471 | B23: 45950 | C23: Stellenbosch/Helderberg | D23: 1 extra as a firefighter | E23: Firefighter, CL, Driver, Planning, Logistical Support, | F23: No | G23: No | H23: Yes | I23: No | J23: Yes | K23: No | L23: No | M23: No | N23: No | O23: No | P23: Yes | Q23: No | R23: No | S23: No | T23: No | U23: No | V23: Yes | W23: No | X23: Yes | Y23: No | Z23: Yes | AA23: No | AB23: No | AC23: No | AD23: No | AE23: No | AF23: No | AG23: No | AH23: No | AI23: No | AJ23: No | AK23: No | AL23: Yes | AM23: No | AN23: Yes | AO23: No | AP23: No | AQ23: No | AR23: Yes | AS23: No | AT23: No | AU23: No | AV23: Yes | AW23: No | AX23: No | AY23: No | AZ23: Yes | BA23: No | BB23: No | BC23: No | BD23: I can almost solely do Saturday standbys, I am almost always bust on Sundays. | BE23: N/A | BF23: N/A
A24: b0929492-fb48-441d-9394-595f49472793 | B24: 45945 | C24: Stellenbosch/Helderberg | D24: I'd rather not, thanks. | E24: Firefighter, CL, Driver, Planning, Logistical Support, | F24: Yes | G24: Yes | H24: Yes | I24: Yes | J24: Yes | K24: Yes | L24: No | M24: No | N24: No | O24: No | P24: No | Q24: No | R24: No | S24: No | T24: No | U24: No | V24: Yes | W24: Yes | X24: Yes | Y24: Yes | Z24: Yes | AA24: Yes | AB24: Yes | AC24: Yes | AD24: Yes | AE24: Yes | AF24: Yes | AG24: Yes | AH24: Yes | AI24: Yes | AJ24: Yes | AK24: Yes | AL24: Yes | AM24: Yes | AN24: Yes | AO24: Yes | AP24: Yes | AQ24: Yes | AR24: Yes | AS24: Yes | AT24: Yes | AU24: Yes | AV24: No | AW24: No | AX24: Yes | AY24: Yes | AZ24: Yes | BA24: Yes | BB24: Yes | BC24: Yes | BD24: Only available at HDB not STB due to transport restraints. | BE24: N/A | BF24: N/A
A25: 67fe2313-2c1e-4fb7-a80e-edb9bbb4e4f3 | B25: 45944 | C25: Newlands | D25: 1 extra as a firefighter, If NWL helitack is run again this year, I would like to opt in | E25: Firefighter, CL, Driver, Planning, Logistical Support, | F25: Yes | G25: No | H25: No | I25: Yes | J25: No | K25: Yes | L25: No | M25: Yes | N25: Yes | O25: No | P25: No | Q25: No | R25: Yes | S25: Yes | T25: Yes | U25: No | V25: Yes | W25: No | X25: Yes | Y25: No | Z25: No | AA25: Yes | AB25: Yes | AC25: No | AD25: Yes | AE25: Yes | AF25: Yes | AG25: Yes | AH25: No | AI25: No | AJ25: Yes | AK25: No | AL25: Yes | AM25: Yes | AN25: No | AO25: No | AP25: Yes | AQ25: Yes | AR25: No | AS25: No | AT25: Yes | AU25: Yes | AV25: Yes | AW25: Yes | AX25: No | AY25: No | AZ25: Yes | BA25: Yes | BB25: Yes | BC25: No | BE25: Newlands | BF25: South Peninsula
A26: 418cff4b-295b-43c1-81fb-d109a37c5c99 | B26: 45940 | C26: Newlands | D26: 1 extra as a firefighter, If NWL helitack is run again this year, I would like to opt in | E26: Firefighter, CL, Driver, Planning, Logistical Support, | F26: Yes | G26: Yes | H26: Yes | I26: Yes | J26: Yes | K26: Yes | L26: Yes | M26: Yes | N26: Yes | O26: Yes | P26: Yes | Q26: Yes | R26: Yes | S26: Yes | T26: No | U26: No | V26: Yes | W26: Yes | X26: Yes | Y26: Yes | Z26: Yes | AA26: Yes | AB26: Yes | AC26: Yes | AD26: Yes | AE26: Yes | AF26: Yes | AG26: Yes | AH26: Yes | AI26: Yes | AJ26: Yes | AK26: Yes | AL26: Yes | AM26: Yes | AN26: Yes | AO26: Yes | AP26: Yes | AQ26: Yes | AR26: Yes | AS26: No | AT26: No | AU26: No | AV26: No | AW26: No | AX26: No | AY26: No | AZ26: No | BA26: No | BB26: No | BC26: No | BE26: Newlands | BF26: Newlands
A27: 663b7f6e-1ca5-4dd5-97d4-dcb92d4d2b17 | B27: 45945 | C27: Newlands | E27: Firefighter, CL, Driver, Planning, Logistical Support, | F27: Yes | G27: Yes | H27: No | I27: Yes | J27: Yes | K27: Yes | L27: Yes | M27: Yes | N27: No | O27: Yes | P27: No | Q27: No | R27: Yes | S27: Yes | T27: Yes | U27: Yes | V27: Yes | W27: Yes | X27: Yes | Y27: Yes | Z27: Yes | AA27: Yes | AB27: Yes | AC27: Yes | AD27: Yes | AE27: Yes | AF27: Yes | AG27: Yes | AH27: Yes | AI27: Yes | AJ27: Yes | AK27: Yes | AL27: No | AM27: Yes | AN27: Yes | AO27: Yes | AP27: Yes | AQ27: Yes | AR27: Yes | AS27: Yes | AT27: Yes | AU27: Yes | AV27: Yes | AW27: Yes | AX27: Yes | AY27: Yes | AZ27: No | BA27: Yes | BB27: Yes | BC27: Yes | BD27: On Sunday 7 December I can't be on STB/HDB standby because I am not available at all on 6 December so cannot be on readiness in the evening. | BE27: Stellenbosch/Helderberg | BF27: N/A
A28: df8f2035-882e-4c59-90d0-51521a59dbd9 | B28: 45951 | C28: Newlands | D28: I'd rather not, thanks. | E28: Firefighter, CL, Driver, Planning, Logistical Support, | F28: No | G28: No | H28: Yes | I28: Yes | J28: Yes | K28: Yes | L28: No | M28: No | N28: No | O28: No | P28: Yes | Q28: Yes | R28: Yes | S28: No | T28: No | U28: Yes | V28: No | W28: Yes | X28: Yes | Y28: Yes | Z28: No | AA28: No | AB28: Yes | AC28: No | AD28: No | AE28: Yes | AF28: Yes | AG28: Yes | AH28: Yes | AI28: No | AJ28: No | AK28: No | AL28: Yes | AM28: Yes | AN28: Yes | AO28: Yes | AP28: Yes | AQ28: Yes | AR28: Yes | AS28: Yes | AT28: No | AU28: No | AV28: Yes | AW28: Yes | AX28: Yes | AY28: Yes | AZ28: Yes | BA28: No | BB28: No | BC28: No | BD28: Mostly random guesses sp if anyone has a serious need to be off I am happy to negotiate | BE28: South Peninsula | BF28: South Peninsula, Stellenbosch/Helderberg
A29: 02372358-f49e-47ba-96dc-869f295bf76e | B29: 45944 | C29: Newlands | D29: If NWL helitack is run again this year, I would like to opt in | E29: Firefighter, CL, Driver, Planning, Logistical Support, | F29: Yes | G29: Yes | H29: Yes | I29: Yes | J29: Yes | K29: Yes | L29: Yes | M29: Yes | N29: Yes | O29: Yes | P29: Yes | Q29: Yes | R29: No | S29: No | T29: Yes | U29: Yes | V29: No | W29: No | X29: Yes | Y29: Yes | Z29: Yes | AA29: Yes | AB29: Yes | AC29: Yes | AD29: Yes | AE29: Yes | AF29: Yes | AG29: Yes | AH29: Yes | AI29: Yes | AJ29: Yes | AK29: Yes | AL29: Yes | AM29: Yes | AN29: Yes | AO29: Yes | AP29: Yes | AQ29: Yes | AR29: Yes | AS29: Yes | AT29: Yes | AU29: Yes | AV29: Yes | AW29: Yes | AX29: Yes | AY29: Yes | AZ29: Yes | BA29: Yes | BB29: Yes | BC29: Yes | BE29: N/A | BF29: South Peninsula
A30: 2b4b032a-e2b6-48a5-a8a8-190822311a7b | B30: 45936 | C30: Stellenbosch/Helderberg | D30: 1 extra as a firefighter | E30: Firefighter, CL, Driver, Planning, Logistical Support, | F30: No | G30: Yes | H30: No | I30: Yes | J30: No | K30: No | L30: No | M30: No | N30: No | O30: No | P30: No | Q30: No | R30: No | S30: No | T30: No | U30: No | V30: No | W30: No | X30: No | Y30: No | Z30: No | AA30: No | AB30: No | AC30: No | AD30: Yes | AE30: Yes | AF30: Yes | AG30: No | AH30: Yes | AI30: No | AJ30: Yes | AK30: No | AL30: Yes | AM30: No | AN30: Yes | AO30: No | AP30: Yes | AQ30: No | AR30: Yes | AS30: No | AT30: Yes | AU30: No | AV30: Yes | AW30: No | AX30: Yes | AY30: No | AZ30: Yes | BA30: No | BB30: Yes | BC30: No | BE30: N/A | BF30: N/A
A31: f4b33818-86cf-422d-bb33-b019464cb18d | B31: 45945 | C31: Newlands | D31: If NWL helitack is run again this year, I would like to opt in | E31: Firefighter, CL, Driver, Planning, Logistical Support, | F31: Yes | G31: Yes | H31: Yes | I31: Yes | J31: Yes | K31: Yes | L31: No | M31: Yes | N31: Yes | O31: Yes | P31: No | Q31: No | R31: No | S31: No | T31: No | U31: No | V31: No | W31: No | X31: No | Y31: No | Z31: No | AA31: No | AB31: No | AC31: No | AD31: No | AE31: No | AF31: No | AG31: No | AH31: Yes | AI31: Yes | AJ31: Yes | AK31: Yes | AL31: Yes | AM31: Yes | AN31: Yes | AO31: Yes | AP31: Yes | AQ31: Yes | AR31: Yes | AS31: Yes | AT31: Yes | AU31: Yes | AV31: Yes | AW31: Yes | AX31: Yes | AY31: Yes | AZ31: Yes | BA31: Yes | BB31: Yes | BC31: Yes | BE31: Newlands | BF31: N/A
A32: fcd6dabf-4df6-4aa0-9883-ed90b0127c8b
A33: 16dcc952-ab7c-45cc-916a-4c1cc364e34c | B33: 45945 | C33: Newlands, South Peninsula, Stellenbosch/Helderberg | D33: 1 extra as a firefighter, 1 extra stand by in a secondary role (eg: as a driver or planning), If NWL helitack is run again this year, I would like to opt in | E33: Firefighter, CL, Driver, Planning, Logistical Support, | F33: Yes | G33: Yes | H33: Yes | I33: Yes | J33: Yes | K33: Yes | L33: No | M33: No | N33: Yes | O33: Yes | P33: Yes | Q33: Yes | R33: Yes | S33: Yes | T33: No | U33: No | V33: Yes | W33: Yes | X33: Yes | Y33: Yes | Z33: Yes | AA33: Yes | AB33: Yes | AC33: Yes | AD33: Yes | AE33: Yes | AF33: Yes | AG33: Yes | AH33: Yes | AI33: Yes | AJ33: Yes | AK33: Yes | AL33: Yes | AM33: Yes | AN33: Yes | AO33: Yes | AP33: Yes | AQ33: Yes | AR33: Yes | AS33: Yes | AT33: Yes | AU33: Yes | AV33: Yes | AW33: Yes | AX33: Yes | AY33: Yes | AZ33: Yes | BA33: Yes | BB33: Yes | BC33: Yes | BE33: Newlands, South Peninsula, Stellenbosch/Helderberg | BF33: Newlands, South Peninsula, Stellenbosch/Helderberg
A34: 1728d1fd-fe5e-426d-9c0d-008352176a3d | B34: 45933 | C34: Newlands | D34: I'd rather not, thanks. | E34: Firefighter, CL, Driver, Planning, Logistical Support, | F34: No | G34: Yes | H34: No | I34: Yes | J34: No | K34: Yes | L34: No | M34: Yes | N34: No | O34: Yes | P34: No | Q34: Yes | R34: No | S34: No | T34: No | U34: No | V34: No | W34: No | X34: No | Y34: No | Z34: No | AA34: Yes | AB34: No | AC34: Yes | AD34: No | AE34: Yes | AF34: No | AG34: Yes | AH34: No | AI34: No | AJ34: No | AK34: No | AL34: No | AM34: No | AN34: No | AO34: No | AP34: No | AQ34: No | AR34: No | AS34: No | AT34: No | AU34: Yes | AV34: No | AW34: Yes | AX34: No | AY34: Yes | AZ34: No | BA34: Yes | BB34: No | BC34: Yes | BE34: N/A | BF34: N/A
A35: 83f9f5b5-b38d-4c62-88ca-9c36b4a412ef | B35: 45933 | C35: Newlands | D35: I'd rather not, thanks. | E35: Firefighter, CL, Driver, Planning, Logistical Support, | F35: Yes | G35: Yes | H35: Yes | I35: Yes | J35: Yes | K35: Yes | L35: Yes | M35: No | N35: Yes | O35: Yes | P35: Yes | Q35: Yes | R35: No | S35: Yes | T35: Yes | U35: Yes | V35: No | W35: Yes | X35: Yes | Y35: Yes | Z35: No | AA35: No | AB35: No | AC35: Yes | AD35: Yes | AE35: Yes | AF35: Yes | AG35: Yes | AH35: No | AI35: Yes | AJ35: No | AK35: No | AL35: No | AM35: No | AN35: No | AO35: Yes | AP35: Yes | AQ35: No | AR35: No | AS35: No | AT35: Yes | AU35: Yes | AV35: No | AW35: No | AX35: Yes | AY35: Yes | AZ35: Yes | BA35: Yes | BB35: Yes | BC35: Yes | BE35: N/A | BF35: N/A
A36: 6ccc288e-dd07-4103-9056-41868c9f3575 | B36: 45942 | C36: Newlands | D36: I'd rather not, thanks. | E36: Firefighter, CL, Driver, Planning, Logistical Support, | F36: No | G36: No | H36: No | I36: No | J36: No | K36: No | L36: Yes | M36: No | N36: No | O36: No | P36: No | Q36: No | R36: No | S36: No | T36: Yes | U36: No | V36: Yes | W36: No | X36: No | Y36: No | Z36: No | AA36: No | AB36: No | AC36: No | AD36: Yes | AE36: No | AF36: No | AG36: No | AH36: Yes | AI36: No | AJ36: No | AK36: No | AL36: No | AM36: No | AN36: No | AO36: No | AP36: No | AQ36: No | AR36: Yes | AS36: No | AT36: No | AU36: No | AV36: No | AW36: No | AX36: No | AY36: No | AZ36: No | BA36: No | BB36: No | BC36: No | BD36: Preferably at Stellenbosch base from February | BE36: Newlands, Stellenbosch/Helderberg | BF36: Newlands, South Peninsula, Stellenbosch/Helderberg
A37: 5a5c8fd0-96bf-4f1a-aeb8-b1b9553b6bf8 | B37: 45940 | C37: Newlands | D37: 1 extra as a firefighter, If NWL helitack is run again this year, I would like to opt in | E37: Firefighter, CL, Driver, Planning, Logistical Support, | F37: No | G37: No | H37: Yes | I37: Yes | J37: Yes | K37: Yes | L37: Yes | M37: Yes | N37: Yes | O37: Yes | P37: Yes | Q37: Yes | R37: Yes | S37: Yes | T37: Yes | U37: Yes | V37: No | W37: No | X37: Yes | Y37: Yes | Z37: Yes | AA37: Yes | AB37: Yes | AC37: Yes | AD37: Yes | AE37: Yes | AF37: Yes | AG37: Yes | AH37: Yes | AI37: Yes | AJ37: Yes | AK37: Yes | AL37: Yes | AM37: Yes | AN37: Yes | AO37: Yes | AP37: Yes | AQ37: Yes | AR37: Yes | AS37: Yes | AT37: Yes | AU37: Yes | AV37: Yes | AW37: Yes | AX37: Yes | AY37: Yes | AZ37: Yes | BA37: Yes | BB37: Yes | BC37: Yes | BE37: South Peninsula | BF37: N/A
A38: 9f28807e-2a1a-4bd2-b285-7250b69bf3be | B38: 45933 | C38: Newlands | D38: 1 extra as a firefighter, If NWL helitack is run again this year, I would like to opt in | E38: Firefighter, CL, Driver, Planning, Logistical Support, | F38: Yes | G38: Yes | H38: Yes | I38: Yes | J38: Yes | K38: Yes | L38: Yes | M38: Yes | N38: Yes | O38: Yes | P38: Yes | Q38: Yes | R38: Yes | S38: Yes | T38: Yes | U38: Yes | V38: Yes | W38: Yes | X38: Yes | Y38: Yes | Z38: Yes | AA38: Yes | AB38: Yes | AC38: Yes | AD38: Yes | AE38: Yes | AF38: Yes | AG38: No | AH38: Yes | AI38: Yes | AJ38: Yes | AK38: Yes | AL38: Yes | AM38: Yes | AN38: Yes | AO38: Yes | AP38: Yes | AQ38: Yes | AR38: Yes | AS38: Yes | AT38: Yes | AU38: Yes | AV38: Yes | AW38: Yes | AX38: Yes | AY38: Yes | AZ38: Yes | BA38: Yes | BB38: Yes | BC38: Yes | BE38: N/A | BF38: N/A
A39: a04d20b6-329b-44ca-91d9-b198e0d8c1a5 | B39: 45944 | C39: Newlands | D39: I'd rather not, thanks. | E39: Firefighter, CL, Driver, Planning, Logistical Support, | F39: No | G39: No | H39: Yes | I39: No | J39: No | K39: No | L39: No | M39: No | N39: Yes | O39: No | P39: No | Q39: No | R39: No | S39: Yes | T39: Yes | U39: Yes | V39: No | W39: No | X39: No | Y39: No | Z39: No | AA39: No | AB39: No | AC39: No | AD39: No | AE39: No | AF39: No | AG39: No | AH39: No | AI39: No | AJ39: No | AK39: No | AL39: No | AM39: No | AN39: No | AO39: No | AP39: No | AQ39: No | AR39: No | AS39: No | AT39: No | AU39: No | AV39: No | AW39: No | AX39: No | AY39: No | AZ39: No | BA39: No | BB39: No | BC39: No | BD39: Unfortunately likely not available in 2026 due to my wife's medical community service. I'll only know for certain towards the end of the year. If I'm placed near NWL, I'm happy to swap shifts to help out others doing Planning, but cannot commit to anything in 2026 until I know where in SA we're being placed. Apologies! | BE39: N/A | BF39: N/A
A40: 0bbe59b3-49e2-499e-99b3-63721c98b235 | B40: 45933 | C40: Newlands | D40: 1 extra as a firefighter | E40: Firefighter, CL, Driver, Planning, Logistical Support, | F40: Yes | G40: Yes | H40: No | I40: Yes | J40: Yes | K40: Yes | L40: Yes | M40: Yes | N40: No | O40: No | P40: Yes | Q40: Yes | R40: Yes | S40: Yes | T40: Yes | U40: Yes | V40: Yes | W40: Yes | X40: Yes | Y40: Yes | Z40: Yes | AA40: Yes | AB40: Yes | AC40: Yes | AD40: Yes | AE40: Yes | AF40: Yes | AG40: Yes | AH40: Yes | AI40: Yes | AJ40: Yes | AK40: Yes | AL40: Yes | AM40: Yes | AN40: Yes | AO40: Yes | AP40: Yes | AQ40: Yes | AR40: Yes | AS40: Yes | AT40: Yes | AU40: Yes | AV40: Yes | AW40: Yes | AX40: Yes | AY40: Yes | AZ40: Yes | BA40: Yes | BB40: Yes | BC40: Yes | BE40: Newlands | BF40: Newlands
...

Sheet Control & Dispatch Availability
A1: Name | B1: Which of the following roles do you intend to qualify in? | C1: November dates [Wednesday, 26 November 2025 - Tuesday, 2 December 2025] | D1: December dates [Wednesday, 3 December 2025 - TTuesday, 9 December 2025] | E1: December dates [Wednesday, 10 December 2025 - Tuesday, 16 December 2025] | F1: December dates [Wednesday, 17 December 2025 - Tuesday, 23 December 2025] | G1: December dates [Wednesday, 24 December 2025 - Tuesday, 30 December 2025] | H1: December dates [Wednesday, 31 December 2025 - Tuesday, 6 January 2026] | I1: January dates [Wednesday, 7 January 2026 - Tuesday, 13 January 2026] | J1: January dates [Wednesday, 14 January 2026 - Tuesday, 20 January 2026] | K1: January dates [Wednesday, 21 January 2026 - Tuesday, 27 January 2026] | L1: January dates [Wednesday, 28 January 2026 - Tuesday, 3 February 2026] | M1: February dates [Wednesday, 4 February 2026 - Tuesday, 10 February 2026] | N1: February dates [Wednesday, 11 February 2026 - Tuesday, 17 February 2026] | O1: February dates [Wednesday, 18 February 2026 - Tuesday, 24 February 2026] | P1: February dates [Wednesday, 25 February 2026 - Tuesday, 3 March 2026] | Q1: March dates [Wednesday, 4 March 2026 - Tuesday, 10 March 2026] | R1: March dates [Wednesday, 11 March 2026 - Tuesday, 17 March 2026] | S1: March dates [Wednesday, 18 March 2026 - Tuesday, 24 March 2026] | T1: March dates [Wednesday, 25 March 2026 - Tuesday, 31 March 2026] | U1: April dates [Wednesday, 1 April 2026 - Tuesday, 7 April 2026] | V1: April dates [Wednesday, 8 April 2026 - Tuesday, 14 April 2026] | W1: April dates [Wednesday, 15 April 2026 - Tuesday, 21 April 2026] | X1: April dates [Wednesday, 22 April 2026 - Tuesday, 28 April 2026] | Y1: Do you also intend to qualify in any other roles? | Z1: November Dates [28 November - 30 November] | AA1: December Dates [5 December - 7 December] | AB1: December Dates [12 December - 14 December] | AC1: December Dates [19 December - 21 December] | AD1: December Dates [26 December - 28 December] | AE1: January Dates [2 January - 4 January] | AF1: January Dates [9 January - 11 January] | AG1: January Dates [16 January - 18 January] | AH1: January Dates [23 January - 25 January] | AI1: January Dates [30 January - 1 February] | AJ1: February Dates [6 February - 8 February] | AK1: February Dates [13 February - 15 February] | AL1: February Dates [20 February - 22 February] | AM1: February Dates [27 February - 1 March] | AN1: March Dates [6 March - 8 March] | AO1: March Dates [13 March - 15 March] | AP1: March Dates [20 March - 22 March] | AQ1: March Dates [27 March - 29 March] | AR1: April Dates [3 April - 5 April] | AS1: April Dates [10 April - 12 April] | AT1: April Dates [17 April - 19 April] | AU1: April Dates [24 April - 26 April] | AV1: Any other notes?
A2: d92c8113-b01c-48e3-a153-cac68ee5c991 | B2: JR Dispatch Role | Z2: No | AA2: No | AB2: Yes | AC2: No | AD2: No | AE2: No | AF2: Yes | AG2: No | AH2: No | AI2: No | AJ2: No | AK2: No | AL2: No | AM2: No | AN2: No | AO2: No | AP2: No | AQ2: No | AR2: No | AS2: Yes | AT2: No | AU2: No
A3: aab0739d-0066-441a-ba0e-d7b5933f42cb | B3: Control Role | C3: No | D3: No | E3: Yes | F3: Yes | G3: Yes | H3: Yes | I3: Yes | J3: Yes | K3: No | L3: No | M3: No | N3: No | O3: Yes | P3: Yes | Q3: Yes | R3: Yes | S3: Yes | T3: Yes | U3: No | V3: Yes | W3: Yes | X3: No | Y3: None
A4: 7c4a5ce9-d43e-42ed-94c5-bb35fbe1fbd8 | B4: Control Role | C4: No | D4: Yes | E4: Yes | F4: Yes | G4: Yes | H4: Yes | I4: Yes | J4: Yes | K4: Yes | L4: Yes | M4: Yes | N4: Yes | O4: Yes | P4: Yes | Q4: Yes | R4: Yes | S4: Yes | T4: Yes | U4: Yes | V4: Yes | W4: Yes | X4: Yes | Y4: None | AV4: Just thanks. That's all.
A5: 13ff5803-e9ed-4dfe-87ce-5ce9f2753aed | B5: SNR Dispatch Role | Z5: No | AA5: Yes | AB5: No | AC5: No | AD5: Yes | AE5: No | AF5: No | AG5: No | AH5: Yes | AI5: No | AJ5: No | AK5: No | AL5: No | AM5: Yes | AN5: No | AO5: No | AP5: No | AQ5: Yes | AR5: No | AS5: No | AT5: Yes | AU5: No
A6: 8b1b54f3-75db-403d-a065-edd4fb979460 | B6: SNR Dispatch Role | Z6: No | AA6: Yes | AB6: Yes | AC6: Yes | AD6: Yes | AE6: Yes | AF6: No | AG6: No | AH6: No | AI6: Yes | AJ6: Yes | AK6: Yes | AL6: No | AM6: Yes | AN6: No | AO6: No | AP6: No | AQ6: No | AR6: No | AS6: No | AT6: No | AU6: No
A7: 2fe8e74b-68c5-4836-8438-2ac96ca217ff | B7: Control Role | C7: No | D7: No | E7: No | F7: No | G7: Yes | H7: Yes | I7: Yes | J7: Yes | K7: Yesx | L7: Yes | M7: Yes | N7: Yesx | O7: Yes | P7: Yes | Q7: Yesx | R7: Yes | S7: Yes | T7: Yes | U7: Yesx | V7: Yes | W7: Yes | X7: Yes | Y7: Dispatcher | Z7: No | AA7: No | AB7: No | AC7: Yes | AD7: Yes | AE7: Yes | AF7: Yes | AG7: Yes | AH7: Yes | AI7: Yes | AJ7: Yes | AK7: Yes | AL7: Yes | AM7: Yes | AN7: Yes | AO7: Yes | AP7: Yes | AQ7: Yes | AR7: Yes | AS7: Yesx | AT7: Yes | AU7: Yes | AV7: Would prefer dispatch and control shifts not to overlap.
A8: 0d76fe11-5ab3-43d8-9867-61b880cd3e5a | B8: OPS Dispatch Role | Z8: No | AA8: Yes | AB8: Yes | AC8: Yes | AD8: No | AE8: Yes | AF8: Yes | AG8: Yes | AH8: Yes | AI8: Yes | AJ8: Yes | AK8: Yes | AL8: Yes | AM8: Yes | AN8: Yes | AO8: No | AP8: No | AQ8: No | AR8: Yes | AS8: No | AT8: Yes | AU8: Yes | AV8: I am currently seeking alternative employment, so my availability is likely to change.
A9: 6bb9dba1-6902-427d-a833-9620cef566aa | B9: Control Role | C9: No | D9: No | E9: No | F9: Yes | G9: Yes | H9: Yes | I9: Yes | J9: Yes | K9: Yes | L9: Yes | M9: No | N9: Yes | O9: Yes | P9: Yes | Q9: Yes | R9: Yes | S9: Yes | T9: No | U9: No | V9: No | W9: Yes | X9: No | Y9: None
A10: c55f9ab9-55a0-4288-b21d-1247242fab41 | B10: SNR Dispatch Role | Z10: No | AA10: Yes | AB10: Yes | AC10: Yes | AD10: No | AE10: No | AF10: Yes | AG10: Yes | AH10: Yes | AI10: Yes | AJ10: Yes | AK10: No | AL10: Yes | AM10: Yes | AN10: Yes | AO10: Yes | AP10: Yes | AQ10: Yes | AR10: Yes | AS10: Yes | AT10: Yes | AU10: Yes
A11: bc0ab80c-202f-48c6-9cdb-c8d9c7f62162 | B11: Control Role | C11: No | D11: No | E11: Yes | F11: No | G11: No | H11: Yes | I11: Yes | J11: Yes | K11: No | L11: No | M11: Yes | N11: No | O11: Yes | P11: Yes | Q11: No | R11: Yes | S11: Yes | T11: Yes | U11: Yes | V11: No | W11: Yes | X11: No | Y11: None
A12: b842684a-6aaf-4b23-a5f4-9633f9319785 | B12: JR Dispatch Role | Z12: No | AA12: No | AB12: No | AC12: Yes | AD12: No | AE12: No | AF12: Yes | AG12: Yes | AH12: Yes | AI12: Yes | AJ12: Yes | AK12: Yes | AL12: Yes | AM12: Yes | AN12: Yes | AO12: Yes | AP12: Yes | AQ12: Yes | AR12: Yes | AS12: Yes | AT12: Yes | AU12: Yes
A13: 15b5198e-f9a7-4e19-8204-9d569410e24f | B13: OPS Dispatch Role | Z13: No | AA13: No | AB13: Yes | AC13: Yes | AD13: No | AE13: No | AF13: Yes | AG13: Yes | AH13: Yes | AI13: Yes | AJ13: Yes | AK13: Yes | AL13: Yes | AM13: Yes | AN13: Yes | AO13: Yes | AP13: Yes | AQ13: No | AR13: No | AS13: Yes | AT13: Yes | AU13: Yes
A14: 0b463554-c421-423f-b357-8f8a26a96163 | B14: SNR Dispatch Role | Z14: No | AA14: No | AB14: No | AC14: Yes | AD14: Yes | AE14: No | AF14: Yes | AG14: Yes | AH14: Yes | AI14: Yes | AJ14: Yes | AK14: Yes | AL14: Yes | AM14: Yes | AN14: Yes | AO14: Yes | AP14: No | AQ14: No | AR14: No | AS14: Yes | AT14: No | AU14: No
A15: f39386d8-a1b1-4395-8a5d-9b2e9f4511ae | B15: SNR Dispatch Role | Z15: No | AA15: No | AB15: No | AC15: No | AD15: No | AE15: No | AF15: No | AG15: No | AH15: Yes | AI15: Yes | AJ15: No | AK15: No | AL15: Yes | AM15: No | AN15: Yes | AO15: Yes | AP15: Yes | AQ15: No | AR15: No | AS15: Yes | AT15: No | AU15: Yes
A16: d8e64b86-e762-49b0-8fcf-e4fa767cb1f0 | B16: Control Role | C16: No | D16: No | E16: No | F16: No | G16: Yes | H16: No | I16: No | J16: No | K16: Yes | L16: Yes | M16: Yes | N16: Yes | O16: Yes | P16: Yes | Q16: No | R16: Yes | S16: Yes | T16: Yes | U16: No | V16: Yes | W16: Yes | X16: Yes | Y16: None
A17: 99555346-6927-4ceb-818c-e7d53b722046 | B17: OPS Dispatch Role | Z17: No | AA17: Yes | AB17: Yes | AC17: No | AD17: Yes | AE17: Yes | AF17: No | AG17: No | AH17: Yes | AI17: No | AJ17: Yes | AK17: No | AL17: Yes | AM17: Yes | AN17: Yes | AO17: No | AP17: Yes | AQ17: No | AR17: Yes | AS17: No | AT17: Yes | AU17: No | AV17: Nope
A18: 790850d5-9599-4bd6-b7ca-43b7033e4c03 | B18: Control Role | C18: Yes | D18: Yes | E18: Yes | F18: No | G18: No | H18: No | I18: Yes | J18: Yes | K18: Yes | L18: Yes | M18: Yes | N18: Yes | O18: Yes | P18: Yes | Q18: Yes | R18: Yes | S18: Yes | T18: Yes | U18: Yes | V18: Yes | W18: Yes | X18: Yes | Y18: None
A19: 47ed41ca-7bfe-4638-b729-059cbfd3fcbf | B19: Control Role | D19: No | H19: Yes | L19: Yes | P19: Yes | X19: Yes
A20: 92061004-e601-453c-8cca-cc912862761e | B20: SNR Dispatch Role | Z20: No | AA20: No | AB20: No | AC20: No | AD20: No | AE20: No | AF20: Yes | AG20: Yes | AH20: No | AI20: No | AJ20: No | AK20: Yes | AL20: No | AM20: No | AN20: No | AO20: No | AP20: No | AQ20: Yes | AR20: No | AS20: Yes | AT20: No | AU20: No | AV20: This is the best I can do for now, with being on duty the whole weekend. I will be able to take over and cover for the day or a night, partially on other weekends, to give others a break.
A21: b0555970-08c9-46d1-b986-9f3044c0d01f | B21: OPS Dispatch Role,Control Primary | C21: Yes | D21: No | E21: No | F21: Yes | G21: Yes | H21: No | I21: Yes | J21: Yes | K21: Yes | L21: Yes | M21: Yesx | N21: Yes | O21: Yes | P21: Yes | Q21: Yes | R21: Yes | S21: No | T21: No | U21: No | V21: Yes | W21: No | X21: No | Z21: Yes | AA21: No | AB21: No | AC21: Yes | AD21: Yes | AE21: No | AF21: Yes | AG21: Yes | AH21: Yes | AI21: Yes | AJ21: Yes | AK21: Yes | AL21: Yes | AM21: Yes | AN21: Yes | AO21: Yes | AP21: No | AQ21: No | AR21: No | AS21: Yes | AT21: No | AU21: No | AV21: Would preffer is Control and Dispatch overlap
A22: 21d06740-0eed-4962-9d2e-b86722bf36d0 | B22: OPS Dispatch Role | Z22: No | AA22: No | AB22: No | AC22: No | AD22: No | AE22: No | AF22: No | AG22: Yes | AH22: No | AI22: Yes | AJ22: No | AK22: Yes | AL22: No | AM22: Yes | AN22: No | AO22: Yes | AP22: Yes | AQ22: Yes | AR22: No | AS22: Yes | AT22: No | AU22: Yes

Sheet VWS Roster
B1: VWS Standby Roster 2025 / 2026 | D1: Last updated | E1: Oranage indiactes tranee Crew Leaders | F1: 45959 | G1: If you can no longer make a standby duty assigned to you, you must find a qualified volunteer willing to SWAP. Swaps are like for like: e.g., CL for CL, ACL for ACL, FF for FF, Driver for Driver, NR for NR. Refer to the Qualifications tab to confirm. Notify your ops manager ASAP of the swap so the roster can be updated. Public Holidays and Special Standby duties are at the bottom of the sheet. | N1: Blue font indicates Truck drivers and assistant truck drivers | O1: Yellow shading: New Recruits | P1: Pink shading: Training drive required. Drivers with # are not yet signed off. | Q1: Red names require one or more evaluations
A3: # | B3: Date | C3: Time | D3: Base | E3: 1. Crew Leader | F3: 2. Assistant CL | G3: 3. Firefighter | H3: 4. Firefighter | I3: 5. Firefighter | J3: 6. Firefighter | K3: 7. Firefighter | L3: 8. Firefighter | M3: Crew Driver | N3: Skid Driver | O3: Planning | P3: Planning Trainee | Q3: Logistics Support | R3: Station/Crew | S3: Date
A4: 1 | B4: 45976 | C4: 12:45-18:00 | D4: NWL HC1 | R4: NWL HC | S4: 45976
D5: SPS HC | R5: SPS HC
D6: HDB HC/SU | R6: HDB HC
A7: 2 | B7: 45977 | C7: 12:45-18:00 | D7: NWL HC1 | R7: NWL HC | S7: 45977
A8: 3 | B8: 45983 | C8: 12:45-18:00 | D8: NWL HC1 | R8: NWL HC | S8: 45983
D9: NWL SU | R9: NWL SU
D10: SPS HC | R10: SPS HC
D11: STB HC | R11: STB HC
A12: 4 | B12: 45984 | C12: 12:45-18:00 | D12: NWL HC1 | R12: NWL HC | S12: 45984
D13: NWL SU | R13: NWL SU
A14: 5 | B14: 45990 | C14: 12:45-18:00 | D14: NWL HC1 | R14: NWL HC1 | S14: 45990
D15: NWL HC2 | R15: NWL HC2
D16: SPS HC | R16: SPS HC
D17: HDB HC/SU | R17: HDB HC
A18: 6 | B18: 45991 | C18: 12:45-18:00 | D18: NWL HC1 | R18: NWL HC | S18: 45991
D19: NWL SU | R19: NWL SU
A20: 7 | B20: 45997 | C20: 12:45-18:00 | D20: NWL HC1 | R20: NWL HC1 | S20: 45997
D21: NWL HC2 | R21: NWL HC2
D22: SPS HC | R22: SPS HC
D23: STB HC | R23: STB HC
A24: 8 | B24: 45998 | C24: 12:45-18:00 | D24: NWL HC1 | R24: NWL HC1 | S24: 45998
D25: NWL HC2 | R25: NWL HC2
A26: 9 | B26: 46004 | C26: 12:45-18:00 | D26: NWL HC1 | R26: NWL HC | S26: 46004
D27: NWL SU | R27: NWL SU
D28: SPS HC | R28: SPS HC
D29: HDB HC/SU | R29: HDB HC
A30: 10 | B30: 46005 | C30: 12:45-18:00 | D30: NWL HC1 | R30: NWL HC | S30: 46005
D31: NWL SU | R31: NWL SU
A32: 11 | B32: 46011 | C32: 12:45-18:00 | D32: NWL HC1 | R32: NWL HC | S32: 46011
D33: NWL SU | R33: NWL SU
D34: SPS HC | R34: SPS HC
D35: STB HC | R35: STB HC
A36: 12 | B36: 46012 | C36: 12:45-18:00 | D36: NWL HC1 | R36: NWL HC | S36: 46012
D37: NWL SU | R37: NWL SU
A38: 13 | B38: 46018 | C38: 12:45-18:00 | D38: NWL HC1 | R38: NWL HC1 | S38: 46018
D39: NWL HC2 | R39: NWL HC2
D40: SPS HC | R40: SPS HC
D41: HDB HC/SU | R41: HDB HC
...

Sheet Control Roster
B1: VWS Newlands Control Duty Roster 2025 / 2026
A2: # | B2: Week Starting | C2: Ending | D2: Control
A3: C1 | B3: 45994 | C3: =B3+6 -> 46000
A4: C2 | B4: =B3+7 -> 46001 | C4: =B4+6 -> 46007
A5: C3 | B5: =B4+7 -> 46008 | C5: =B5+6 -> 46014
A6: C4 | B6: =B5+7 -> 46015 | C6: =B6+6 -> 46021
A7: C5 | B7: =B6+7 -> 46022 | C7: =B7+6 -> 46028
A8: C6 | B8: =B7+7 -> 46029 | C8: =B8+6 -> 46035
A9: C7 | B9: =B8+7 -> 46036 | C9: =B9+6 -> 46042
A10: C8 | B10: =B9+7 -> 46043 | C10: =B10+6 -> 46049
A11: C9 | B11: =B10+7 -> 46050 | C11: =B11+6 -> 46056
A12: C10 | B12: =B11+7 -> 46057 | C12: =B12+6 -> 46063
A13: C11 | B13: =B12+7 -> 46064 | C13: =B13+6 -> 46070
A14: C12 | B14: =B13+7 -> 46071 | C14: =B14+6 -> 46077
A15: C13 | B15: =B14+7 -> 46078 | C15: =B15+6 -> 46084
... A23: C21 | B23: =B22+7 -> 46134 | C23: =B23+6 -> 46140

Sheet Dispatch Roster
A1: VWS DISPATCH Duty Roster 2025 / 2026 | B1: Post swaps on the Dispatch Team WhatsApp group for approval
A2: Week Starting | B2: Ending | C2: Dispatch Manager | D2: Dispatcher | E2: Trainee Dispatcher
A3: Week Starting | B3: Ending | C3: Dispatch Manager | D3: Dispatcher | E3: Trainee Dispatcher
A4: 45989 | B4: =A4+2 -> 45991
A5: =A4+7 -> 45996 | B5: =A5+2 -> 45998
A6: =A5+7 -> 46003 | B6: =A6+2 -> 46005
A7: =A6+7 -> 46010 | B7: =A7+2 -> 46012
A8: =A7+7 -> 46017 | B8: =A8+2 -> 46019
A9: =A8+7 -> 46024 | B9: =A9+2 -> 46026
A10: =A9+7 -> 46031 | B10: =A10+2 -> 46033
A11: =A10+7 -> 46038 | B11: =A11+2 -> 46040
A12: =A11+7 -> 46045 | B12: =A12+2 -> 46047
A13: =A12+7 -> 46052 | B13: =A13+2 -> 46054
A14: =A13+7 -> 46059 | B14: =A14+2 -> 46061
A15: =A14+7 -> 46066 | B15: =A15+2 -> 46068
A16: =A15+7 -> 46073 | B16: =A16+2 -> 46075
... A25: =A24+7 -> 46136 | B25: =A25+2 -> 46138

Sheet Helitack
A1: Name and Surname | B1: Role | C1: Station
A2: 48ce16c1-a830-40f8-a3fd-2f773f62c0e4 | B2: CL | C2: NWL
A3: 609e664c-15ee-4afe-b2a1-187435d0de90 | B3: CL | C3: NWL
A4: 473d1a1c-13f8-4e67-b901-ab6e8d84b298 | B4: CL | C4: SPS
A5: 522ce146-bd45-4e51-8bc2-17541f1e4a50 | B5: CL | C5: SPS
A6: 837e6dc1-a0cc-42dc-add0-e43ee86aff21 | B6: CL | C6: NWL
A7: 7be5c85c-6197-43e9-80dd-ad3d990b6fe6 | B7: CL | C7: NWL
A8: 21d06740-0eed-4962-9d2e-b86722bf36d0 | B8: CL | C8: SPS
A9: 9c525960-6b87-497e-85cd-7fd81d31bbfb | B9: ACL | C9: NWL
A10: 9adccede-8dc2-4a5f-b5fd-5edc989b7da6 | B10: ACL | C10: NWL
A11: f777d2a5-7066-4db0-a878-aaed32df72bb | B11: ACL | C11: SPS
A12: 9793fef7-c054-4ec2-83fd-06596ab60780 | B12: ACL | C12: NWL
... A35: 418cff4b-295b-43c1-81fb-d109a37c5c99 | B35: FF2YR | C35: NWL

Sheet Quals
A1: Name | B1: Home | C1: Qu | D1: Ops | E1: CL | F1: ACL | G1: FF | H1: DRV | I1: SDrv | J1: TDrv | K1: Plan | L1: Disp | M1: LS | N1: NR | O1: Unfit | P1: Comments
A2: 013abc1a-3775-402c-9d8b-d4582957136a | B2: STB | C2: Q | G2: FF
A3: 0230e24f-2ddd-4f7c-bc20-12df8000da70 | B3: NWL | K3: Plan (trainee) | N3: Y
A4: 02372358-f49e-47ba-96dc-869f295bf76e | B4: NWL | C4: Q | F4: ACL | G4: FF | K4: Plan (trainee)
A5: 028ef489-2a33-43c6-9d30-c9902ff2f06f | B5: NWL | C5: Q | G5: FF | N5: Y
A6: 02f22d58-165c-40b5-85ec-6db5c37d3a07 | B6: STB | C6: Q | G6: FF | N6: Y
A7: 03623462-87e9-4ea1-a75b-ab298fd03ebc | B7: NWL | C7: Q | G7: FF | H7: Drv | M7: LS
A8: 04c0b819-4154-4a86-a0c2-726c404408a2 | B8: NWL | C8: Q | G8: FF | M8: LS (inactive)
A9: 07f70f6e-3c74-449d-bd5a-aeb7ae8cd1a6 | B9: HDB | C9: Q | G9: FF | H9: Drv | I9: S Drv (trainee) | N9: Y
A10: 083a3bfc-e606-4d77-95f4-60fa82956233 | B10: NWL | M10: LS
A11: 08c7d967-5f5a-400d-bcdd-8286f0669e59 | B11: SPS | M11: LS
A12: 09a3ea12-6309-41fb-90f2-6f190601a25b | B12: NWL/STB | C12: Q | G12: FF
A13: 0a03a20f-58a0-4ea7-8a18-ee53363bd69e | B13: STB | C13: Q | D13: STLD | E13: CL | F13: ACL | G13: FF
A14: 0a12a9da-1985-4a29-a8b1-9eea5bf81acd | B14: NWL | C14: Q | G14: FF
A15: 0a928a88-2c09-4827-9fbb-4943318f0814 | B15: NWL | C15: Q | E15: CL | F15: ACL | G15: FF | H15: Drv | I15: S Drv
A16: 0b384f7a-e454-447f-b18a-020a9f9e9635 | B16: NWL | C16: Q | G16: FF | H16: Drv (trainee)
A17: 0b396ecd-f02a-41ed-bf0d-ef87ef177e09 | B17: SPS | G17: FF (inactive) | O17: Unfit | P17: back op
A18: 0b463554-c421-423f-b357-8f8a26a96163 | B18: NWL | C18: Q | G18: FF | H18: Drv (inactive) | I18: S Drv (inactive) | L18: Disp
A19: 0b72e418-d733-4834-a178-f3f84be71698 | B19: NWL | C19: Q | G19: FF | P19: No Role Update '25
A20: 0bbe59b3-49e2-499e-99b3-63721c98b235 | B20: NWL | C20: Q | G20: FF | N20: Y
A21: 0bce89a0-fd2b-47b2-a592-d65e15739ead | B21: SPS | C21: Q | F21: ACL | G21: FF
A22: 0cb1b1fb-7b0d-432f-935a-6bf7f42e7e0f | B22: NWL | K22: Plan (trainee)
A23: 0cdb4bb1-a12c-4b11-87a1-69d48588e7d3 | B23: SPS | C23: Q | G23: FF | N23: Y
A24: 0d76fe11-5ab3-43d8-9867-61b880cd3e5a | B24: NWL | C24: Q | D24: ICT5 | E24: CL (inactive) | G24: FF (inactive) | H24: Drv | L24: Disp (mgr)
A25: 0ed3f298-8e1b-4aab-aa20-26f52fcc3df9 | B25: NWL | C25: Q | G25: FF | N25: Y
A26: 0f0b573c-df94-45bf-9336-01a7a37cef83 | B26: NWL | C26: Q | G26: FF | H26: Drv (trainee)
A27: 0fb1540e-685c-4125-a9c7-c6c5adb2ad5d | B27: HDB | C27: Q | G27: FF
A28: 103935c7-1360-485c-9767-ce4be9b19ea0 | B28: NWL | C28: Q | F28: ACL | G28: FF
A29: 10804e44-fc06-4d65-8115-05da4966a5b4 | B29: SPS | C29: Q | G29: FF
A30: 10ac1613-9172-42eb-a4af-d8c8dcc36910 | B30: NWL | G30: FF (inactive) | P30: Injury 10/25
A31: 10e886d3-5e96-4407-8957-be031052b72a | B31: HDB | C31: Q | G31: FF | H31: Drv | I31: S Drv
A32: 12f832cc-5871-45a3-9fdc-18c74f71e5b2 | B32: SPS | C32: Q | H32: Drv | I32: S Drv (trainee) | N32: Y
A33: 13a93f32-7296-4db6-9072-42c8ae1100fa | B33: NWL | C33: Q | F33: ACL | G33: FF | P33: Mentored by eeb7b005-5b73-4491-8192-3162de381b32, pair when ever possible
A34: 13ff5803-e9ed-4dfe-87ce-5ce9f2753aed | B34: SPS | L34: Disp
A35: 14941c3e-7d83-4b92-aa58-537837bcd938 | B35: STB | C35: Q | H35: Drv | I35: S Drv
A36: 154c6da7-561a-4464-845b-ae0e52455e0e | B36: SPS | C36: Q | G36: FF | N36: Y
A37: 15871ddb-8931-4660-8e70-9d4c6b5f67d2 | B37: NWL | C37: Q | G37: FF (inactive) | H37: Drv
A38: 15b5198e-f9a7-4e19-8204-9d569410e24f | B38: HDB | L38: Disp (mgr)
A39: 1609c509-2b1f-43d0-8a67-475a2ebf8fe3 | B39: SPS | C39: Q | G39: FF | N39: Y
A40: 1697e9d6-ae4b-4abd-9692-65bc324eb726 | B40: NWL | C40: Q | G40: FF | H40: Drv (trainee)
...

Sheet Qualifications_Clean
A1: Member ID | B1: Role | C1: Qualified | D1: Trainee | E1: Senior | F1: Notes | G1: Status
A2: {=_xlfn._xlws.FILTER(Quals!$A$2:$A$332,Quals!$E$2:$E$332="CL","")} -> 0a03a20f-58a0-4ea7-8a18-ee53363bd69e | B2: {=IF(_xlfn.ANCHORARRAY(A2)<>"","CL","")} -> CL | C2: {=IF(_xlfn.ANCHORARRAY(A2)<>"",1,"")} -> 1 | D2: {=IF(_xlfn.ANCHORARRAY(A2)<>"",0,"")} -> 0 | E2: {=IF(_xlfn.ANCHORARRAY(A2)<>"",1,"")} -> 1 | F2: ="" | G2: {=IF(_xlfn.ANCHORARRAY(A2)<>"","active","")} -> active
A3: 0a928a88-2c09-4827-9fbb-4943318f0814 | B3: CL | C3: 1 | D3: 0 | E3: 1 | G3: active
A4: 1c30300d-8d81-46e3-bb4a-43d3cc3a55e2 | B4: CL | C4: 1 | D4: 0 | E4: 1 | G4: active
A5: 21d06740-0eed-4962-9d2e-b86722bf36d0 | B5: CL | C5: 1 | D5: 0 | E5: 1 | G5: active
A6: 2644e420-6fa8-484f-bd58-1f05104677e8 | B6: CL | C6: 1 | D6: 0 | E6: 1 | G6: active
A7: 31512974-2c3d-45f1-8e38-d022a12280cc | B7: CL | C7: 1 | D7: 0 | E7: 1 | G7: active
A8: 35a4aedf-191d-4208-8724-4adb5a4172fd | B8: CL | C8: 1 | D8: 0 | E8: 1 | G8: active
A9: 378ce48b-5c37-4a89-b796-316ec088cd7e | B9: CL | C9: 1 | D9: 0 | E9: 1 | G9: active
A10: 473d1a1c-13f8-4e67-b901-ab6e8d84b298 | B10: CL | C10: 1 | D10: 0 | E10: 1 | G10: active
A11: 48ce16c1-a830-40f8-a3fd-2f773f62c0e4 | B11: CL | C11: 1 | D11: 0 | E11: 1 | G11: active
A12: 4faa654f-edb7-4e0c-83c1-5e877f91f026 | B12: CL | C12: 1 | D12: 0 | E12: 1 | G12: active
A13: 522ce146-bd45-4e51-8bc2-17541f1e4a50 | B13: CL | C13: 1 | D13: 0 | E13: 1 | G13: active
A14: 55206ea7-a827-4544-b37f-91b4701b65a3 | B14: CL | C14: 1 | D14: 0 | E14: 1 | G14: active
... A38: ffbc20e9-c35d-43ca-a055-721a8dacb0d6 | B38: CL | C38: 1 | D38: 0 | E38: 1 | G38: active
A39: {=_xlfn._xlws.FILTER(Quals!$A$2:$A$332,Quals!$F$2:$F$332="ACL","")} -> 02372358-f49e-47ba-96dc-869f295bf76e | B39: {=IF(_xlfn.ANCHORARRAY(A39)<>"","ACL","")} -> ACL | C39: {=IF(_xlfn.ANCHORARRAY(A39)<>"",1,"")} -> 1 | D39: {=IF(_xlfn.ANCHORARRAY(A39)<>"",0,"")} -> 0 | E39: {=IF(_xlfn.ANCHORARRAY(A39)<>"",1,"")} -> 1 | G39: {=IF(_xlfn.ANCHORARRAY(A39)<>"","active","")} -> active
A40: 0a03a20f-58a0-4ea7-8a18-ee53363bd69e | B40: ACL | C40: 1 | D40: 0 | E40: 1 | G40: active
A41: 0a928a88-2c09-4827-9fbb-4943318f0814 | B41: ACL | C41: 1 | D41: 0 | E41: 1 | G41: active
A42: 0bce89a0-fd2b-47b2-a592-d65e15739ead | B42: ACL | C42: 1 | D42: 0 | E42: 1 | G42: active
A43: 103935c7-1360-485c-9767-ce4be9b19ea0 | B43: ACL | C43: 1 | D43: 0 | E43: 1 | G43: active
A44: 13a93f32-7296-4db6-9072-42c8ae1100fa | B44: ACL | C44: 1 | D44: 0 | E44: 1 | G44: active
A45: 1c30300d-8d81-46e3-bb4a-43d3cc3a55e2 | B45: ACL | C45: 1 | D45: 0 | E45: 1 | G45: active
A46: 21c1fa65-cdc0-4d94-b471-29c5a96a940c | B46: ACL | C46: 1 | D46: 0 | E46: 1 | G46: active
A47: 21d06740-0eed-4962-9d2e-b86722bf36d0 | B47: ACL | C47: 1 | D47: 0 | E47: 1 | G47: active
A48: 2644e420-6fa8-484f-bd58-1f05104677e8 | B48: ACL | C48: 1 | D48: 0 | E48: 1 | G48: active
